<?xml version="1.0" ?>
<robot name="bot" xmlns:xacro="http://www.ros.org/wiki/xacro">

<xacro:include filename="$(find bot_description)/urdf/materials.xacro" />
<xacro:include filename="$(find bot_description)/urdf/bot.trans" />
<xacro:include filename="$(find bot_description)/urdf/bot.gazebo" />
<link name="base_link">
  <inertial>
    <origin xyz="0.0019988554986570734 -1.3222279788666387e-08 0.06263210787557169" rpy="0 0 0"/>
    <mass value="4.421664916903425"/>
    <inertia ixx="0.018516" iyy="0.01894" izz="0.028858" ixy="-0.0" iyz="-0.0" ixz="-0.000572"/>
  </inertial>
  <visual>
    <origin xyz="0 0 0" rpy="0 0 0"/>
    <geometry>
      <mesh filename="package://bot_description/meshes/base_link.stl" scale="0.001 0.001 0.001"/>
    </geometry>
    <material name="silver"/>
  </visual>
  <collision>
    <origin xyz="0 0 0" rpy="0 0 0"/>
    <geometry>
      <mesh filename="package://bot_description/meshes/base_link.stl" scale="0.001 0.001 0.001"/>
    </geometry>
  </collision>
</link>

<link name="right_wheel_1">
  <inertial>
    <origin xyz="2.2204460492503132e-17 -0.010000000000000009 1.3877787807814457e-17" rpy="0 0 0"/>
    <mass value="0.21036104408437248"/>
    <inertia ixx="0.000196" iyy="0.000379" izz="0.000196" ixy="-0.0" iyz="-0.0" ixz="0.0"/>
  </inertial>
  <visual>
    <origin xyz="-0.0 0.1 -0.06" rpy="0 0 0"/>
    <geometry>
      <mesh filename="package://bot_description/meshes/right_wheel_1.stl" scale="0.001 0.001 0.001"/>
    </geometry>
    <material name="silver"/>
  </visual>
  <collision>
    <origin xyz="-0.0 0.1 -0.06" rpy="0 0 0"/>
    <geometry>
      <mesh filename="package://bot_description/meshes/right_wheel_1.stl" scale="0.001 0.001 0.001"/>
    </geometry>
  </collision>
</link>

<link name="left_wheel_1">
  <inertial>
    <origin xyz="2.2204460492503132e-17 0.010000000000000009 1.3877787807814457e-17" rpy="0 0 0"/>
    <mass value="0.21036104408437248"/>
    <inertia ixx="0.000196" iyy="0.000379" izz="0.000196" ixy="0.0" iyz="0.0" ixz="0.0"/>
  </inertial>
  <visual>
    <origin xyz="-0.0 -0.1 -0.06" rpy="0 0 0"/>
    <geometry>
      <mesh filename="package://bot_description/meshes/left_wheel_1.stl" scale="0.001 0.001 0.001"/>
    </geometry>
    <material name="silver"/>
  </visual>
  <collision>
    <origin xyz="-0.0 -0.1 -0.06" rpy="0 0 0"/>
    <geometry>
      <mesh filename="package://bot_description/meshes/left_wheel_1.stl" scale="0.001 0.001 0.001"/>
    </geometry>
  </collision>
</link>

<link name="lidar_1">
  <inertial>
    <origin xyz="6.938893903907228e-18 -5.5845130209510275e-18 0.012499999999999983" rpy="0 0 0"/>
    <mass value="0.10789485809488791"/>
    <inertia ixx="4.1e-05" iyy="4.1e-05" izz="7e-05" ixy="-0.0" iyz="0.0" ixz="0.0"/>
  </inertial>
  <visual>
    <origin xyz="-0.05 -0.0 -0.145" rpy="0 0 0"/>
    <geometry>
      <mesh filename="package://bot_description/meshes/lidar_1.stl" scale="0.001 0.001 0.001"/>
    </geometry>
    <material name="silver"/>
  </visual>
  <collision>
    <origin xyz="-0.05 -0.0 -0.145" rpy="0 0 0"/>
    <geometry>
      <mesh filename="package://bot_description/meshes/lidar_1.stl" scale="0.001 0.001 0.001"/>
    </geometry>
  </collision>
</link>

<joint name="Revolute1" type="continuous">
  <origin xyz="0.02 -0.1 0.06" rpy="0 0 0"/>
  <parent link="base_link"/>
  <child link="right_wheel_1"/>
  <axis xyz="0.0 1.0 0.0"/>
</joint>

<joint name="Revolute2" type="continuous">
  <origin xyz="0.02 0.1 0.06" rpy="0 0 0"/>
  <parent link="base_link"/>
  <child link="left_wheel_1"/>
  <axis xyz="0.0 1.0 0.0"/>
</joint>

<joint name="Rigid 3" type="fixed">
  <origin xyz="0.05 0.0 0.145" rpy="0 0 0"/>
  <parent link="base_link"/>
  <child link="lidar_1"/>
</joint>

</robot>
